Workbook

Sheet Legend
A1: Date (DD/MM/YY): | E1: q1: | G1: q3:
A2: Description: | E2: q2: | G2: q4:
A3: Sample type: | B3: Control plate
A4: Well | B4: Row | C4: Column | D4: Code | E4: Fraction | F4: Treatment | G4: Concentration | H4: Units | I4: KCFL_Plate | J4: KCFL_Well | K4: Merge_Image
A5: A01 | B5: A | C5: 01 | D5: =Names!$B$2 -> DMSO | E5: =IF(LEFT(D5,2)="KC",IF(_xlfn.CEILING.MATH(C5/2)-2<1,"",_xlfn.CEILING.MATH(C5/2)-2),"") | F5: =IF(E5="",D5,_xlfn.CONCAT(D5,"_",E5)) -> DMSO | G5: =Concentrations!$B$2 -> 0 | H5: % | I5: {=IF(MOD(COLUMN(INDIRECT(B5&1)),2)=1,IF(MOD(C5,2)=1,$F$1,$F$2),IF(MOD(C5,2)=1,$H$1,$H$2))} -> 0
A6: A02 | B6: A | C6: 02 | D6: =Names!$C$2 -> DMSO | E6: =IF(LEFT(D6,2)="KC",IF(_xlfn.CEILING.MATH(C6/2)-2<1,"",_xlfn.CEILING.MATH(C6/2)-2),"") | F6: =IF(E6="",D6,_xlfn.CONCAT(D6,"_",E6)) -> DMSO | G6: =Concentrations!$C$2 -> 0 | H6: % | I6: {=IF(MOD(COLUMN(INDIRECT(B6&1)),2)=1,IF(MOD(C6,2)=1,$F$1,$F$2),IF(MOD(C6,2)=1,$H$1,$H$2))} -> 0
A7: A03 | B7: A | C7: 03 | D7: =Names!$D$2 -> 0 | E7: =IF(LEFT(D7,2)="KC",IF(_xlfn.CEILING.MATH(C7/2)-2<1,"",_xlfn.CEILING.MATH(C7/2)-2),"") | F7: =IF(E7="",D7,_xlfn.CONCAT(D7,"_",E7)) -> 0 | G7: =Concentrations!$D$2 -> 0 | H7: % | I7: {=IF(MOD(COLUMN(INDIRECT(B7&1)),2)=1,IF(MOD(C7,2)=1,$F$1,$F$2),IF(MOD(C7,2)=1,$H$1,$H$2))} -> 0
A8: A04 | B8: A | C8: 04 | D8: =Names!$E$2 -> 0 | E8: =IF(LEFT(D8,2)="KC",IF(_xlfn.CEILING.MATH(C8/2)-2<1,"",_xlfn.CEILING.MATH(C8/2)-2),"") | F8: =IF(E8="",D8,_xlfn.CONCAT(D8,"_",E8)) -> 0 | G8: =Concentrations!$E$2 -> 0 | H8: % | I8: {=IF(MOD(COLUMN(INDIRECT(B8&1)),2)=1,IF(MOD(C8,2)=1,$F$1,$F$2),IF(MOD(C8,2)=1,$H$1,$H$2))} -> 0
A9: A05 | B9: A | C9: 05 | D9: =Names!$F$2 -> 0 | E9: =IF(LEFT(D9,2)="KC",IF(_xlfn.CEILING.MATH(C9/2)-2<1,"",_xlfn.CEILING.MATH(C9/2)-2),"") | F9: =IF(E9="",D9,_xlfn.CONCAT(D9,"_",E9)) -> 0 | G9: =Concentrations!$F$2 -> 0 | H9: % | I9: {=IF(MOD(COLUMN(INDIRECT(B9&1)),2)=1,IF(MOD(C9,2)=1,$F$1,$F$2),IF(MOD(C9,2)=1,$H$1,$H$2))} -> 0
A10: A06 | B10: A | C10: 06 | D10: =Names!$G$2 -> 0 | E10: =IF(LEFT(D10,2)="KC",IF(_xlfn.CEILING.MATH(C10/2)-2<1,"",_xlfn.CEILING.MATH(C10/2)-2),"") | F10: =IF(E10="",D10,_xlfn.CONCAT(D10,"_",E10)) -> 0 | G10: =Concentrations!$G$2 -> 0 | H10: % | I10: {=IF(MOD(COLUMN(INDIRECT(B10&1)),2)=1,IF(MOD(C10,2)=1,$F$1,$F$2),IF(MOD(C10,2)=1,$H$1,$H$2))} -> 0
A11: A07 | B11: A | C11: 07 | D11: =Names!$H$2 -> 0 | E11: =IF(LEFT(D11,2)="KC",IF(_xlfn.CEILING.MATH(C11/2)-2<1,"",_xlfn.CEILING.MATH(C11/2)-2),"") | F11: =IF(E11="",D11,_xlfn.CONCAT(D11,"_",E11)) -> 0 | G11: =Concentrations!$H$2 -> 0 | H11: % | I11: {=IF(MOD(COLUMN(INDIRECT(B11&1)),2)=1,IF(MOD(C11,2)=1,$F$1,$F$2),IF(MOD(C11,2)=1,$H$1,$H$2))} -> 0
A12: A08 | B12: A | C12: 08 | D12: =Names!$I$2 -> 0 | E12: =IF(LEFT(D12,2)="KC",IF(_xlfn.CEILING.MATH(C12/2)-2<1,"",_xlfn.CEILING.MATH(C12/2)-2),"") | F12: =IF(E12="",D12,_xlfn.CONCAT(D12,"_",E12)) -> 0 | G12: =Concentrations!$I$2 -> 0 | H12: % | I12: {=IF(MOD(COLUMN(INDIRECT(B12&1)),2)=1,IF(MOD(C12,2)=1,$F$1,$F$2),IF(MOD(C12,2)=1,$H$1,$H$2))} -> 0
A13: A09 | B13: A | C13: 09 | D13: =Names!$J$2 -> 0 | E13: =IF(LEFT(D13,2)="KC",IF(_xlfn.CEILING.MATH(C13/2)-2<1,"",_xlfn.CEILING.MATH(C13/2)-2),"") | F13: =IF(E13="",D13,_xlfn.CONCAT(D13,"_",E13)) -> 0 | G13: =Concentrations!$J$2 -> 0 | H13: % | I13: {=IF(MOD(COLUMN(INDIRECT(B13&1)),2)=1,IF(MOD(C13,2)=1,$F$1,$F$2),IF(MOD(C13,2)=1,$H$1,$H$2))} -> 0
A14: A10 | B14: A | C14: 10 | D14: =Names!$K$2 -> 0 | E14: =IF(LEFT(D14,2)="KC",IF(_xlfn.CEILING.MATH(C14/2)-2<1,"",_xlfn.CEILING.MATH(C14/2)-2),"") | F14: =IF(E14="",D14,_xlfn.CONCAT(D14,"_",E14)) -> 0 | G14: =Concentrations!$K$2 -> 0 | H14: % | I14: {=IF(MOD(COLUMN(INDIRECT(B14&1)),2)=1,IF(MOD(C14,2)=1,$F$1,$F$2),IF(MOD(C14,2)=1,$H$1,$H$2))} -> 0
A15: A11 | B15: A | C15: 11 | D15: =Names!$L$2 -> 0 | E15: =IF(LEFT(D15,2)="KC",IF(_xlfn.CEILING.MATH(C15/2)-2<1,"",_xlfn.CEILING.MATH(C15/2)-2),"") | F15: =IF(E15="",D15,_xlfn.CONCAT(D15,"_",E15)) -> 0 | G15: =Concentrations!$L$2 -> 0 | H15: % | I15: {=IF(MOD(COLUMN(INDIRECT(B15&1)),2)=1,IF(MOD(C15,2)=1,$F$1,$F$2),IF(MOD(C15,2)=1,$H$1,$H$2))} -> 0
A16: A12 | B16: A | C16: 12 | D16: =Names!$M$2 -> 0 | E16: =IF(LEFT(D16,2)="KC",IF(_xlfn.CEILING.MATH(C16/2)-2<1,"",_xlfn.CEILING.MATH(C16/2)-2),"") | F16: =IF(E16="",D16,_xlfn.CONCAT(D16,"_",E16)) -> 0 | G16: =Concentrations!$M$2 -> 0 | H16: % | I16: {=IF(MOD(COLUMN(INDIRECT(B16&1)),2)=1,IF(MOD(C16,2)=1,$F$1,$F$2),IF(MOD(C16,2)=1,$H$1,$H$2))} -> 0
A17: A13 | B17: A | C17: 13 | D17: =Names!$N$2 -> 0 | E17: =IF(LEFT(D17,2)="KC",IF(_xlfn.CEILING.MATH(C17/2)-2<1,"",_xlfn.CEILING.MATH(C17/2)-2),"") | F17: =IF(E17="",D17,_xlfn.CONCAT(D17,"_",E17)) -> 0 | G17: =Concentrations!$N$2 -> 0 | H17: % | I17: {=IF(MOD(COLUMN(INDIRECT(B17&1)),2)=1,IF(MOD(C17,2)=1,$F$1,$F$2),IF(MOD(C17,2)=1,$H$1,$H$2))} -> 0
A18: A14 | B18: A | C18: 14 | D18: =Names!$O$2 -> 0 | E18: =IF(LEFT(D18,2)="KC",IF(_xlfn.CEILING.MATH(C18/2)-2<1,"",_xlfn.CEILING.MATH(C18/2)-2),"") | F18: =IF(E18="",D18,_xlfn.CONCAT(D18,"_",E18)) -> 0 | G18: =Concentrations!$O$2 -> 0 | H18: % | I18: {=IF(MOD(COLUMN(INDIRECT(B18&1)),2)=1,IF(MOD(C18,2)=1,$F$1,$F$2),IF(MOD(C18,2)=1,$H$1,$H$2))} -> 0
A19: A15 | B19: A | C19: 15 | D19: =Names!$P$2 -> 0 | E19: =IF(LEFT(D19,2)="KC",IF(_xlfn.CEILING.MATH(C19/2)-2<1,"",_xlfn.CEILING.MATH(C19/2)-2),"") | F19: =IF(E19="",D19,_xlfn.CONCAT(D19,"_",E19)) -> 0 | G19: =Concentrations!$P$2 -> 0 | H19: % | I19: {=IF(MOD(COLUMN(INDIRECT(B19&1)),2)=1,IF(MOD(C19,2)=1,$F$1,$F$2),IF(MOD(C19,2)=1,$H$1,$H$2))} -> 0
A20: A16 | B20: A | C20: 16 | D20: =Names!$Q$2 -> 0 | E20: =IF(LEFT(D20,2)="KC",IF(_xlfn.CEILING.MATH(C20/2)-2<1,"",_xlfn.CEILING.MATH(C20/2)-2),"") | F20: =IF(E20="",D20,_xlfn.CONCAT(D20,"_",E20)) -> 0 | G20: =Concentrations!$Q$2 -> 0 | H20: % | I20: {=IF(MOD(COLUMN(INDIRECT(B20&1)),2)=1,IF(MOD(C20,2)=1,$F$1,$F$2),IF(MOD(C20,2)=1,$H$1,$H$2))} -> 0
A21: A17 | B21: A | C21: 17 | D21: =Names!$R$2 -> 0 | E21: =IF(LEFT(D21,2)="KC",IF(_xlfn.CEILING.MATH(C21/2)-2<1,"",_xlfn.CEILING.MATH(C21/2)-2),"") | F21: =IF(E21="",D21,_xlfn.CONCAT(D21,"_",E21)) -> 0 | G21: =Concentrations!$R$2 -> 0 | H21: % | I21: {=IF(MOD(COLUMN(INDIRECT(B21&1)),2)=1,IF(MOD(C21,2)=1,$F$1,$F$2),IF(MOD(C21,2)=1,$H$1,$H$2))} -> 0
A22: A18 | B22: A | C22: 18 | D22: =Names!$S$2 -> 0 | E22: =IF(LEFT(D22,2)="KC",IF(_xlfn.CEILING.MATH(C22/2)-2<1,"",_xlfn.CEILING.MATH(C22/2)-2),"") | F22: =IF(E22="",D22,_xlfn.CONCAT(D22,"_",E22)) -> 0 | G22: =Concentrations!$S$2 -> 0 | H22: % | I22: {=IF(MOD(COLUMN(INDIRECT(B22&1)),2)=1,IF(MOD(C22,2)=1,$F$1,$F$2),IF(MOD(C22,2)=1,$H$1,$H$2))} -> 0
A23: A19 | B23: A | C23: 19 | D23: =Names!$T$2 -> 0 | E23: =IF(LEFT(D23,2)="KC",IF(_xlfn.CEILING.MATH(C23/2)-2<1,"",_xlfn.CEILING.MATH(C23/2)-2),"") | F23: =IF(E23="",D23,_xlfn.CONCAT(D23,"_",E23)) -> 0 | G23: =Concentrations!$T$2 -> 0 | H23: % | I23: {=IF(MOD(COLUMN(INDIRECT(B23&1)),2)=1,IF(MOD(C23,2)=1,$F$1,$F$2),IF(MOD(C23,2)=1,$H$1,$H$2))} -> 0
A24: A20 | B24: A | C24: 20 | D24: =Names!$U$2 -> 0 | E24: =IF(LEFT(D24,2)="KC",IF(_xlfn.CEILING.MATH(C24/2)-2<1,"",_xlfn.CEILING.MATH(C24/2)-2),"") | F24: =IF(E24="",D24,_xlfn.CONCAT(D24,"_",E24)) -> 0 | G24: =Concentrations!$U$2 -> 0 | H24: % | I24: {=IF(MOD(COLUMN(INDIRECT(B24&1)),2)=1,IF(MOD(C24,2)=1,$F$1,$F$2),IF(MOD(C24,2)=1,$H$1,$H$2))} -> 0
A25: A21 | B25: A | C25: 21 | D25: =Names!$V$2 -> 0 | E25: =IF(LEFT(D25,2)="KC",IF(_xlfn.CEILING.MATH(C25/2)-2<1,"",_xlfn.CEILING.MATH(C25/2)-2),"") | F25: =IF(E25="",D25,_xlfn.CONCAT(D25,"_",E25)) -> 0 | G25: =Concentrations!$V$2 -> 0 | H25: % | I25: {=IF(MOD(COLUMN(INDIRECT(B25&1)),2)=1,IF(MOD(C25,2)=1,$F$1,$F$2),IF(MOD(C25,2)=1,$H$1,$H$2))} -> 0
A26: A22 | B26: A | C26: 22 | D26: =Names!$W$2 -> 0 | E26: =IF(LEFT(D26,2)="KC",IF(_xlfn.CEILING.MATH(C26/2)-2<1,"",_xlfn.CEILING.MATH(C26/2)-2),"") | F26: =IF(E26="",D26,_xlfn.CONCAT(D26,"_",E26)) -> 0 | G26: =Concentrations!$W$2 -> 0 | H26: % | I26: {=IF(MOD(COLUMN(INDIRECT(B26&1)),2)=1,IF(MOD(C26,2)=1,$F$1,$F$2),IF(MOD(C26,2)=1,$H$1,$H$2))} -> 0
A27: A23 | B27: A | C27: 23 | D27: =Names!$X$2 -> DMSO | E27: =IF(LEFT(D27,2)="KC",IF(_xlfn.CEILING.MATH(C27/2)-2<1,"",_xlfn.CEILING.MATH(C27/2)-2),"") | F27: =IF(E27="",D27,_xlfn.CONCAT(D27,"_",E27)) -> DMSO | G27: =Concentrations!$X$2 -> 0 | H27: % | I27: {=IF(MOD(COLUMN(INDIRECT(B27&1)),2)=1,IF(MOD(C27,2)=1,$F$1,$F$2),IF(MOD(C27,2)=1,$H$1,$H$2))} -> 0
A28: A24 | B28: A | C28: 24 | D28: =Names!$Y$2 -> DMSO | E28: =IF(LEFT(D28,2)="KC",IF(_xlfn.CEILING.MATH(C28/2)-2<1,"",_xlfn.CEILING.MATH(C28/2)-2),"") | F28: =IF(E28="",D28,_xlfn.CONCAT(D28,"_",E28)) -> DMSO | G28: =Concentrations!$Y$2 -> 0 | H28: % | I28: {=IF(MOD(COLUMN(INDIRECT(B28&1)),2)=1,IF(MOD(C28,2)=1,$F$1,$F$2),IF(MOD(C28,2)=1,$H$1,$H$2))} -> 0
A29: B01 | B29: B | C29: 01 | D29: =Names!$B$3 -> Emetine dihydrochloride | E29: =IF(LEFT(D29,2)="KC",IF(_xlfn.CEILING.MATH(C29/2)-2<1,"",_xlfn.CEILING.MATH(C29/2)-2),"") | F29: =IF(E29="",D29,_xlfn.CONCAT(D29,"_",E29)) -> Emetine dihydrochloride | G29: =Concentrations!$B$3 -> 5 | H29: µM | I29: {=IF(MOD(COLUMN(INDIRECT(B29&1)),2)=1,IF(MOD(C29,2)=1,$F$1,$F$2),IF(MOD(C29,2)=1,$H$1,$H$2))} -> 0
A30: B02 | B30: B | C30: 02 | D30: =Names!$C$3 -> Cyclohexamide | E30: =IF(LEFT(D30,2)="KC",IF(_xlfn.CEILING.MATH(C30/2)-2<1,"",_xlfn.CEILING.MATH(C30/2)-2),"") | F30: =IF(E30="",D30,_xlfn.CONCAT(D30,"_",E30)) -> Cyclohexamide | G30: =Concentrations!$C$3 -> 1 | H30: µM | I30: {=IF(MOD(COLUMN(INDIRECT(B30&1)),2)=1,IF(MOD(C30,2)=1,$F$1,$F$2),IF(MOD(C30,2)=1,$H$1,$H$2))} -> 0
A31: B03 | B31: B | C31: 03 | D31: =Names!$D$3 -> 0 | E31: =IF(LEFT(D31,2)="KC",IF(_xlfn.CEILING.MATH(C31/2)-2<1,"",_xlfn.CEILING.MATH(C31/2)-2),"") | F31: =IF(E31="",D31,_xlfn.CONCAT(D31,"_",E31)) -> 0 | G31: =Concentrations!$D$3 -> 0 | H31: µM | I31: {=IF(MOD(COLUMN(INDIRECT(B31&1)),2)=1,IF(MOD(C31,2)=1,$F$1,$F$2),IF(MOD(C31,2)=1,$H$1,$H$2))} -> 0
A32: B04 | B32: B | C32: 04 | D32: =Names!$E$3 -> 0 | E32: =IF(LEFT(D32,2)="KC",IF(_xlfn.CEILING.MATH(C32/2)-2<1,"",_xlfn.CEILING.MATH(C32/2)-2),"") | F32: =IF(E32="",D32,_xlfn.CONCAT(D32,"_",E32)) -> 0 | G32: =Concentrations!$E$3 -> 0 | H32: µM | I32: {=IF(MOD(COLUMN(INDIRECT(B32&1)),2)=1,IF(MOD(C32,2)=1,$F$1,$F$2),IF(MOD(C32,2)=1,$H$1,$H$2))} -> 0
A33: B05 | B33: B | C33: 05 | D33: =Names!$F$3 -> 0 | E33: =IF(LEFT(D33,2)="KC",IF(_xlfn.CEILING.MATH(C33/2)-2<1,"",_xlfn.CEILING.MATH(C33/2)-2),"") | F33: =IF(E33="",D33,_xlfn.CONCAT(D33,"_",E33)) -> 0 | G33: =Concentrations!$F$3 -> 0 | H33: % | I33: {=IF(MOD(COLUMN(INDIRECT(B33&1)),2)=1,IF(MOD(C33,2)=1,$F$1,$F$2),IF(MOD(C33,2)=1,$H$1,$H$2))} -> 0
A34: B06 | B34: B | C34: 06 | D34: =Names!$G$3 -> 0 | E34: =IF(LEFT(D34,2)="KC",IF(_xlfn.CEILING.MATH(C34/2)-2<1,"",_xlfn.CEILING.MATH(C34/2)-2),"") | F34: =IF(E34="",D34,_xlfn.CONCAT(D34,"_",E34)) -> 0 | G34: =Concentrations!$G$3 -> 0 | H34: % | I34: {=IF(MOD(COLUMN(INDIRECT(B34&1)),2)=1,IF(MOD(C34,2)=1,$F$1,$F$2),IF(MOD(C34,2)=1,$H$1,$H$2))} -> 0
A35: B07 | B35: B | C35: 07 | D35: =Names!$H$3 -> 0 | E35: =IF(LEFT(D35,2)="KC",IF(_xlfn.CEILING.MATH(C35/2)-2<1,"",_xlfn.CEILING.MATH(C35/2)-2),"") | F35: =IF(E35="",D35,_xlfn.CONCAT(D35,"_",E35)) -> 0 | G35: =Concentrations!$H$3 -> 0 | H35: % | I35: {=IF(MOD(COLUMN(INDIRECT(B35&1)),2)=1,IF(MOD(C35,2)=1,$F$1,$F$2),IF(MOD(C35,2)=1,$H$1,$H$2))} -> 0
A36: B08 | B36: B | C36: 08 | D36: =Names!$I$3 -> 0 | E36: =IF(LEFT(D36,2)="KC",IF(_xlfn.CEILING.MATH(C36/2)-2<1,"",_xlfn.CEILING.MATH(C36/2)-2),"") | F36: =IF(E36="",D36,_xlfn.CONCAT(D36,"_",E36)) -> 0 | G36: =Concentrations!$I$3 -> 0 | H36: % | I36: {=IF(MOD(COLUMN(INDIRECT(B36&1)),2)=1,IF(MOD(C36,2)=1,$F$1,$F$2),IF(MOD(C36,2)=1,$H$1,$H$2))} -> 0
A37: B09 | B37: B | C37: 09 | D37: =Names!$J$3 -> 0 | E37: =IF(LEFT(D37,2)="KC",IF(_xlfn.CEILING.MATH(C37/2)-2<1,"",_xlfn.CEILING.MATH(C37/2)-2),"") | F37: =IF(E37="",D37,_xlfn.CONCAT(D37,"_",E37)) -> 0 | G37: =Concentrations!$J$3 -> 0 | H37: % | I37: {=IF(MOD(COLUMN(INDIRECT(B37&1)),2)=1,IF(MOD(C37,2)=1,$F$1,$F$2),IF(MOD(C37,2)=1,$H$1,$H$2))} -> 0
A38: B10 | B38: B | C38: 10 | D38: =Names!$K$3 -> 0 | E38: =IF(LEFT(D38,2)="KC",IF(_xlfn.CEILING.MATH(C38/2)-2<1,"",_xlfn.CEILING.MATH(C38/2)-2),"") | F38: =IF(E38="",D38,_xlfn.CONCAT(D38,"_",E38)) -> 0 | G38: =Concentrations!$K$3 -> 0 | H38: % | I38: {=IF(MOD(COLUMN(INDIRECT(B38&1)),2)=1,IF(MOD(C38,2)=1,$F$1,$F$2),IF(MOD(C38,2)=1,$H$1,$H$2))} -> 0
A39: B11 | B39: B | C39: 11 | D39: =Names!$L$3 -> 0 | E39: =IF(LEFT(D39,2)="KC",IF(_xlfn.CEILING.MATH(C39/2)-2<1,"",_xlfn.CEILING.MATH(C39/2)-2),"") | F39: =IF(E39="",D39,_xlfn.CONCAT(D39,"_",E39)) -> 0 | G39: =Concentrations!$L$3 -> 0 | H39: % | I39: {=IF(MOD(COLUMN(INDIRECT(B39&1)),2)=1,IF(MOD(C39,2)=1,$F$1,$F$2),IF(MOD(C39,2)=1,$H$1,$H$2))} -> 0
A40: B12 | B40: B | C40: 12 | D40: =Names!$M$3 -> 0 | E40: =IF(LEFT(D40,2)="KC",IF(_xlfn.CEILING.MATH(C40/2)-2<1,"",_xlfn.CEILING.MATH(C40/2)-2),"") | F40: =IF(E40="",D40,_xlfn.CONCAT(D40,"_",E40)) -> 0 | G40: =Concentrations!$M$3 -> 0 | H40: % | I40: {=IF(MOD(COLUMN(INDIRECT(B40&1)),2)=1,IF(MOD(C40,2)=1,$F$1,$F$2),IF(MOD(C40,2)=1,$H$1,$H$2))} -> 0
...

Sheet Sheet1
A1: =Names!$B$2 -> DMSO
A2: =Names!$C$2 -> DMSO
A3: =Names!$D$2 -> 0
A4: =Names!$E$2 -> 0
A5: =Names!$F$2 -> 0
A6: =Names!$G$2 -> 0
A7: =Names!$H$2 -> 0
A8: =Names!$I$2 -> 0
A9: =Names!$J$2 -> 0
A10: =Names!$K$2 -> 0
A11: =Names!$L$2 -> 0
A12: =Names!$M$2 -> 0
A13: =Names!$N$2 -> 0
A14: =Names!$O$2 -> 0
A15: =Names!$P$2 -> 0
A16: =Names!$Q$2 -> 0
A17: =Names!$R$2 -> 0
A18: =Names!$S$2 -> 0
A19: =Names!$T$2 -> 0
A20: =Names!$U$2 -> 0
A21: =Names!$V$2 -> 0
A22: =Names!$W$2 -> 0
A23: =Names!$X$2 -> DMSO
A24: =Names!$Y$2 -> DMSO
A25: =Names!$B$3 -> Emetine dihydrochloride
A26: =Names!$C$3 -> Cyclohexamide
A27: =Names!$D$3 -> 0
A28: =Names!$E$3 -> 0
A29: =Names!$F$3 -> 0
A30: =Names!$G$3 -> 0
A31: =Names!$H$3 -> 0
A32: =Names!$I$3 -> 0
A33: =Names!$J$3 -> 0
A34: =Names!$K$3 -> 0
A35: =Names!$L$3 -> 0
A36: =Names!$M$3 -> 0
A37: =Names!$N$3 -> 0
A38: =Names!$O$3 -> 0
A39: =Names!$P$3 -> 0
A40: =Names!$Q$3 -> 0
...

Sheet Names
B1: 1 | C1: 2 | D1: 3 | E1: 4 | F1: 5 | G1: 6 | H1: 7 | I1: 8 | J1: 9 | K1: 10 | L1: 11 | M1: 12 | N1: 13 | O1: 14 | P1: 15 | Q1: 16 | R1: 17 | S1: 18 | T1: 19 | U1: 20 | V1: 21 | W1: 22 | X1: 23 | Y1: 24
A2: A | B2: DMSO | C2: DMSO | X2: DMSO | Y2: DMSO
A3: B | B3: Emetine dihydrochloride | C3: Cyclohexamide | X3: DMSO | Y3: DMSO
A4: C | B4: DMSO | C4: DMSO | X4: DMSO | Y4: DMSO
A5: D | B5: Repaglinide | C5: Parbendazol | X5: DMSO | Y5: DMSO
A6: E | B6: DMSO | C6: DMSO | X6: DMSO | Y6: DMSO
A7: F | B7: Cyclohexamide | C7: Fenbendazole | X7: DMSO | Y7: DMSO
A8: G | B8: DMSO | C8: DMSO | X8: DMSO | Y8: DMSO
A9: H | B9: Parbendazol | C9: Emetine dihydrochloride | X9: DMSO | Y9: DMSO
A10: I | B10: DMSO | C10: DMSO | X10: DMSO | Y10: DMSO
A11: J | B11: Fenbendazole | C11: Repaglinide | X11: DMSO | Y11: DMSO
A12: K | B12: DMSO | C12: DMSO | X12: DMSO | Y12: DMSO
A13: L | B13: Emetine dihydrochloride | C13: Cyclohexamide | X13: DMSO | Y13: DMSO
... A17: P | B17: DMSO | C17: Fenbendazole | X17: DMSO | Y17: DMSO

Sheet Concentrations
B1: 1 | C1: 2 | D1: 3 | E1: 4 | F1: 5 | G1: 6 | H1: 7 | I1: 8 | J1: 9 | K1: 10 | L1: 11 | M1: 12 | N1: 13 | O1: 14 | P1: 15 | Q1: 16 | R1: 17 | S1: 18 | T1: 19 | U1: 20 | V1: 21 | W1: 22 | X1: 23 | Y1: 24
A2: A | B2: 0 | C2: 0 | X2: 0 | Y2: 0
A3: B | B3: 5 | C3: 1 | X3: 0 | Y3: 0
A4: C | B4: 0 | C4: 0 | X4: 0 | Y4: 0
A5: D | B5: 5 | C5: 1 | X5: 0 | Y5: 0
A6: E | B6: 0 | C6: 0 | X6: 0 | Y6: 0
A7: F | B7: 5 | C7: 1 | X7: 0 | Y7: 0
A8: G | B8: 0 | C8: 0 | X8: 0 | Y8: 0
A9: H | B9: 5 | C9: 0.3 | X9: 0 | Y9: 0
A10: I | B10: 0 | C10: 0 | X10: 0 | Y10: 0
A11: J | B11: 5 | C11: 0.3 | X11: 0 | Y11: 0
A12: K | B12: 0 | C12: 0 | X12: 0 | Y12: 0
A13: L | B13: 1 | C13: 0.3 | X13: 0 | Y13: 0
... A17: P | B17: 0 | C17: 0.3 | X17: 0 | Y17: 0
